<sdf version='1.6'>
  <model name='v_battery'>
    <link name='v_battery_base_link'>
      <pose frame=''>0 0 0 0 -0 0</pose>
      <inertial>
        <pose frame=''>-0.177939 0.001405 -0.182317 0 -0 0</pose>
        <mass>2.14786</mass>
        <inertia>
          <ixx>0.0444602</ixx>
          <ixy>-0.000641562</ixy>
          <ixz>-0.00551719</ixz>
          <iyy>0.0897722</iyy>
          <iyz>-0.00105284</iyz>
          <izz>0.0457645</izz>
        </inertia>
      </inertial>
      <collision name='v_battery_base_link_collision'>
        <pose frame=''>0 0 0 0 -0 0</pose>
        <geometry>
          <mesh>
            <scale>1 1 1</scale>
            <uri>model://battery_pack_describe/meshes/v_battery_base_link.STL</uri>
          </mesh>
        </geometry>
        <surface>
          <contact>
            <ode/>
          </contact>
          <friction>
            <ode/>
          </friction>
        </surface>
      </collision>
      <collision name='v_battery_base_link_fixed_joint_lump__v_battery_nut_Link_collision_1'>
        <pose frame=''>0.057323 -0.038452 0 0 -0 2.7485</pose>
        <geometry>
          <mesh>
            <scale>1 1 1</scale>
            <uri>model://battery_pack_describe/meshes/v_battery_nut_Link.STL</uri>
          </mesh>
        </geometry>
        <surface>
          <contact>
            <ode/>
          </contact>
          <friction>
            <ode/>
          </friction>
        </surface>
      </collision>
      <visual name='v_battery_base_link_visual'>
        <pose frame=''>0 0 0 0 -0 0</pose>
        <geometry>
          <mesh>
            <scale>1 1 1</scale>
            <uri>model://battery_pack_describe/meshes/v_battery_base_link.STL</uri>
          </mesh>
        </geometry>
        <material>
          <script>
            <uri>model://battery_pack_describe/materials/scripts</uri>
            <uri>model://battery_pack_describe/materials/textures/</uri>
            <name>MyGroundPlane/Image</name>
          </script>
        </material>
      </visual>
      <visual name='v_battery_base_link_fixed_joint_lump__v_battery_nut_Link_visual_1'>
        <pose frame=''>0.057323 -0.038452 0 0 -0 2.7485</pose>
        <geometry>
          <mesh>
            <scale>1 1 1</scale>
            <uri>model://battery_pack_describe/meshes/v_battery_nut_Link.STL</uri>
          </mesh>
        </geometry>
        <material>
          <script>
            <uri>model://battery_pack_describe/materials/scripts</uri>
            <uri>model://battery_pack_describe/materials/textures/</uri>
            <name>MyGroundPlane/Image</name>
          </script>
        </material>
      </visual>
      <velocity_decay/>
      <gravity>1</gravity>
      <velocity_decay/>
    </link>
    <link name='v_battery_bolt_Link'>
      <pose frame=''>0.057323 -0.038452 0 -2.7485 1.57079 3.14159</pose>
      <inertial>
        <pose frame=''>-0.002248 -0 0 0 -0 0</pose>
        <mass>0.0100431</mass>
        <inertia>
          <ixx>8.16036e-08</ixx>
          <ixy>-2.67875e-13</ixy>
          <ixz>1.25078e-13</ixz>
          <iyy>1.22915e-06</iyy>
          <iyz>5.98229e-14</iyz>
          <izz>1.22915e-06</izz>
        </inertia>
      </inertial>
      <collision name='v_battery_bolt_Link_collision'>
        <pose frame=''>0 0 0 0 -0 0</pose>
        <geometry>
          <mesh>
            <scale>1 1 1</scale>
            <uri>model://battery_pack_describe/meshes/v_battery_bolt_Link.STL</uri>
          </mesh>
        </geometry>
        <surface>
          <contact>
            <ode/>
          </contact>
          <friction>
            <ode/>
          </friction>
        </surface>
      </collision>
      <visual name='v_battery_bolt_Link_visual'>
        <pose frame=''>0 0 0 0 -0 0</pose>
        <geometry>
          <mesh>
            <scale>1 1 1</scale>
            <uri>model://battery_pack_describe/meshes/v_battery_bolt_Link.STL</uri>
          </mesh>
        </geometry>
        <material>
          <script>
            <uri>model://battery_pack_describe/materials/scripts</uri>
            <uri>model://battery_pack_describe/materials/textures/</uri>
            <name>MyGroundPlane/Image</name>
          </script>
        </material>
      </visual>
      <gravity>1</gravity>
      <velocity_decay/>
    </link>
    <joint name='v_battery_bolt_joint' type='revolute'>
      <child>v_battery_bolt_Link</child>
      <parent>v_battery_base_link</parent>
      <axis>
        <xyz>1 0 0</xyz>
        <limit>
          <lower>-1e+16</lower>
          <upper>1e+16</upper>
        </limit>
        <dynamics>
          <spring_reference>0</spring_reference>
          <spring_stiffness>0</spring_stiffness>
        </dynamics>
        <use_parent_model_frame>0</use_parent_model_frame>
      </axis>
    </joint>
  </model>
</sdf>
