<?xml version="1.0" encoding="utf-8"?>
<!-- =================================================================================== -->
<!-- |    This document was autogenerated by xacro from tilt_battery.xacro             | -->
<!-- |    EDITING THIS FILE BY HAND IS NOT RECOMMENDED                                 | -->
<!-- =================================================================================== -->
<!-- This URDF was automatically created by SolidWorks to URDF Exporter! Originally created by Stephen Brawner (brawner@gmail.com) 
     Commit Version: 1.5.1-0-g916b5db  Build Version: 1.5.7152.31018
     For more information, please see http://wiki.ros.org/sw_urdf_exporter -->
<robot name="battery_pack_describe">
  <link name="tilt_base_link">
    <inertial>
      <origin rpy="0 0 0" xyz="-0.17823 0.0014541 -0.18254"/>
      <mass value="2.1452"/>
      <inertia ixx="0.04437" ixy="-0.00066651" ixz="-0.0054047" iyy="0.089539" iyz="-0.0010719" izz="0.045613"/>
    </inertial>
    <visual>
      <origin rpy="0 0 0" xyz="0 0 0"/>
      <geometry>
        <mesh filename="package://battery_pack_describe/meshes/tilt_base_link.STL"/>
      </geometry>
      <material name="">
        <color rgba="0.79216 0.81961 0.93333 1"/>
      </material>
    </visual>
    <collision>
      <origin rpy="0 0 0" xyz="0 0 0"/>
      <geometry>
        <mesh filename="package://battery_pack_describe/meshes/tilt_base_link.STL"/>
      </geometry>
    </collision>
  </link>
  <gazebo reference="tilt_base_link">
    <material>Gazebo/FlatBlack</material>
  </gazebo>
  <link name="tilt_bolt_Link">
    <inertial>
      <origin rpy="0 0 0" xyz="-0.00384797059870837 -2.26255488650073E-09 1.06046859488229E-09"/>
      <mass value="0.0100430554001659"/>
      <inertia ixx="8.16036443975724E-08" ixy="-2.55938176329654E-13" ixz="1.19279973102044E-13" iyy="1.22914669997157E-06" iyz="5.5743255490632E-14" izz="1.22914647668468E-06"/>
    </inertial>
    <visual>
      <origin rpy="0 0 0" xyz="0 0 0"/>
      <geometry>
        <mesh filename="package://battery_pack_describe/meshes/tilt_bolt_Link.STL"/>
      </geometry>
      <material name="">
        <color rgba="0.776470588235294 0.756862745098039 0.737254901960784 1"/>
      </material>
    </visual>
    <collision>
      <origin rpy="0 0 0" xyz="0 0 0"/>
      <geometry>
        <mesh filename="package://battery_pack_describe/meshes/tilt_bolt_Link.STL"/>
      </geometry>
    </collision>
  </link>
  <gazebo reference="tilt_bolt_Link">
    <material>Gazebo/FlatBlack</material>
  </gazebo>
  <joint name="tilt_bolt_joint" type="continuous">
    <origin rpy="0.7854 0.7854 -1.5708" xyz="0.055323 0.03596 0.031184"/>
    <parent link="tilt_base_link"/>
    <child link="tilt_bolt_Link"/>
    <axis xyz="1 0 0"/>
  </joint>
  <link name="tilt_nut_Link">
    <inertial>
      <origin rpy="0 0 0" xyz="-8.23260327964537E-10 1.38777878078145E-17 -6.0243313042968E-07"/>
      <mass value="0.00265736664598247"/>
      <inertia ixx="2.79753045005072E-08" ixy="-7.03103520670074E-24" ixz="1.31797003103789E-18" iyy="2.79771327058772E-08" iyz="-4.83267733644929E-14" izz="4.46160415460722E-08"/>
    </inertial>
    <visual>
      <origin rpy="0 0 0" xyz="0 0 0"/>
      <geometry>
        <mesh filename="package://battery_pack_describe/meshes/tilt_nut_Link.STL"/>
      </geometry>
      <material name="">
        <color rgba="0.776470588235294 0.756862745098039 0.737254901960784 1"/>
      </material>
    </visual>
    <collision>
      <origin rpy="0 0 0" xyz="0 0 0"/>
      <geometry>
        <mesh filename="package://battery_pack_describe/meshes/tilt_nut_Link.STL"/>
      </geometry>
    </collision>
  </link>
  <gazebo reference="tilt_nut_Link">
    <material>Gazebo/FlatBlack</material>
  </gazebo>
  <joint name="tilt_nut_joint" type="continuous">
    <origin rpy="2.5261 -0.5236 -0.61548" xyz="0.055323 0.032323 0.027548"/>
    <parent link="tilt_base_link"/>
    <child link="tilt_nut_Link"/>
    <axis xyz="0 0 1"/>
  </joint>
</robot>

